Workbook

Sheet Form Responses 1
B1: Email Address | C1: What transect did you survey? (they are in alphabetical order by county, if your transect is not bellow, then choose "other" at the end and enter the name of the transect in the comment box at the end of this section) | D1: Date you did your survey | E1: Names of observers | F1: If this is a NEW Route: Starting Latitude (in decimal degrees), for example, the latitude for Tallahassee would be: 30.43812. You can use Google Map to get this. Right click on location, and choose "what's here". | G1: If this is a NEW Route:Starting Longitude (in decimal degrees), for example, the latitude for Tallahassee would be: -84.28158. It is negative because it is 84W. | H1: If this is a NEW Route:Ending Latitude (in decimal degrees) if this is a circular route, choose point that is farthest away from starting Latitude. | I1: If this is a NEW Route:Ending Longitude (in decimal degrees). If this is a circular route, choose point that is farthest away from starting Longitude. | J1: Route Start Time | K1: Weather: temperature (optional) | L1: Wind (optional) | M1: Rain (optional) | N1: Did you do a complete survey (all birds) or a focal survey? | O1: Any additional survey comments (if you are doing a new survey, please include its name here) | P1: American Oystercatcher (target species, remember to enter information in focal species section) | Q1: American Avocet | R1: Back-bellied Plover | S1: Dunlin | T1: Greater Yellowlegs (if not sure, put in Yellowlegs species count at end) | U1: Killdeer | V1: Least Sandpiper | W1: Lesser Yellowlegs (if not sure, put in Yellowlegs species count at end) | X1: Long-billed Curlew | Y1: Long-billed Dowitcher (if not sure, put in Dowitcher species count at end) | Z1: Short-billed Dowitcher (if not sure, put in Dowitcher species count at end) | AA1: Dowitcher (species unknown) | AB1: Marbled Godwit | AC1: Piping Plover (target species, remember to enter information in focal species section) | AD1: Red Knot (target species, remember to enter information in focal species section) | AE1: Ruddy Turnstone | AF1: Sanderling | AG1: Semi-palmated Plover | AH1: Semi-palmated Sandpiper (if not sure, put in Sandpiper species count at end) | AI1: Snowy Plover (target species, remember to enter information in focal species section) | AJ1: Spotted Sandpiper | AK1: Western Sandpiper (if not sure, put in Sandpiper species count at end) | AL1: Whimbrel | AM1: Willet | AN1: Wilson's Plover (target species, remember to enter information in focal species section) | AO1: Wilson's Snipe | AP1: Sandpiper (species unknown) | AQ1: Yellowlegs (species unknown) | AR1: Black Skimmer (target species, remember to enter information in focal species section) | AS1: Bonaparte's Gull | AT1: Brown Booby | AU1: Brown Pelican | AV1: Caspian Tern | AW1: Common Tern | AX1: Double-crested Cormorant | AY1: Forster's Tern | AZ1: Glaucous Gull | BA1: Great Black-backed Gull | BB1: Herring Gull | BC1: Laughing Gull | BD1: Lesser Black-backed Gull | BE1: Ring-billed Gull | BF1: Royal Tern | BG1: Sandwich Tern | BH1: Vega Gull | BI1: White Pelican | BJ1: Do you have group or focal points to enter data for? | BK1: Point 1 Latitude (in decimal degrees), for example, the latitude for Tallahassee would be: 30.43812. You can use Google Map to get this. Right click on location, and choose "what's here". | BL1: 1 Longitude (in decimal degrees), for example, the latitude for Tallahassee would be: -84.28158. It is negative because it is 84W. | BM1: 1 Number of American Oystercatchers (at this location) | BN1: 1 Band/Flag Codes for American Oystercatchers (for each individual list: band/flag code, orientation, color, and positions - upper left, lower left, upper right, lower right, and if you reported the band to another site) | BO1: 1 Number of Black Skimmers (at this location) | BP1: 1 Band/Flag Codes for Black Skimmers (for each individual list: band code and color and if you reported the band to another site) | BQ1: 1 Number of Piping Plovers (at this location) | BR1: 1 Band/Flag Codes for Piping Plovers (for each individual list: band/flag code, orientation, color, and positions - upper left, lower left, upper right, lower right, and if you reported the band to another site) | BS1: 1 Number of Red Knots (at this location) | BT1: 1 Band/Flag Codes for Red Knots (for each individual list: band/flag code, orientation, color, and positions - upper left, lower left, upper right, lower right, and if you reported the band to another site) | BU1: 1 Number of Snowy Plovers (at this location) | BV1: 1 Band/Flag Codes for Snowy Plover (for each individual list: band/flag code, orientation, color, and positions - upper left, lower left, upper right, lower right, and if you reported the band to another site) | BW1: 1 Number of Wilson's Plovers (at this location) | BX1: 1 Band/Flag Codes for Wilson's Plover (for each individual list: band/flag code, orientation, color, and positions - upper left, lower left, upper right, lower right, and if you reported the band to another site) | BY1: 1 Any other non-focal species you want to include and information about bands | BZ1: Do you have more group or focal points to enter? | CA1: Point 2 Latitude (in decimal degrees), for example, the latitude for Tallahassee would be: 30.43812. You can use Google Map to get this. Right click on location, and choose "what's here". | CB1: Point 2 Longitude (in decimal degrees), for example, the latitude for Tallahassee would be: -84.28158. It is negative because it is 84W. | CC1: 2 Number of American Oystercatchers (at this location) | CD1: 2 Band/Flag Codes for American Oystercatchers (for each individual list: band/flag code, orientation, color, and positions - upper left, lower left, upper right, lower right, and if you reported the band to another site) | CE1: 2 Number of Black Skimmers (at this location) | CF1: 2 Band/Flag Codes for Black Skimmers (for each individual list: band code and color and if you reported the band to another site) | CG1: 2 Number of Piping Plovers (at this location) | CH1: 2 Band/Flag Codes for Piping Plovers (for each individual list: band/flag code, orientation, color, and positions - upper left, lower left, upper right, lower right, and if you reported the band to another site) | CI1: 2 Number of Red Knots (at this location) | CJ1: 2 Band/Flag Codes for Red Knots (for each individual list: band/flag code, orientation, color, and positions - upper left, lower left, upper right, lower right, and if you reported the band to another site) | CK1: 2 Number of Snowy Plovers (at this location) | CL1: 2 Band/Flag Codes for Snowy Plover (for each individual list: band/flag code, orientation, color, and positions - upper left, lower left, upper right, lower right, and if you reported the band to another site) | CM1: 2 Number of Wilson's Plovers (at this location) | CN1: 2 Band/Flag Codes for Wilson's Plover (for each individual list: band/flag code, orientation, color, and positions - upper left, lower left, upper right, lower right, and if you reported the band to another site) | CO1: 2 Any other non-focal species you want to include and information about bands | CP1: Do you have more group or focal points to enter? | CQ1: Point 3 Latitude (in decimal degrees), for example, the latitude for Tallahassee would be: 30.43812. You can use Google Map to get this. Right click on location, and choose "what's here". | CR1: Point 3 Longitude (in decimal degrees), for example, the latitude for Tallahassee would be: -84.28158. It is negative because it is 84W. | CS1: 3 Number of American Oystercatchers (at this location) | CT1: 3 Band/Flag Codes for American Oystercatchers (for each individual list: band/flag code, orientation, color, and positions - upper left, lower left, upper right, lower right, and if you reported the band to another site) | CU1: 3 Number of Black Skimmers (at this location) | CV1: 3 Band/Flag Codes for Black Skimmers (for each individual list: band code and color and if you reported the band to another site) | CW1: 3 Number of Piping Plovers (at this location) | CX1: 3 Band/Flag Codes for Piping Plovers (for each individual list: band/flag code, orientation, color, and positions - upper left, lower left, upper right, lower right, and if you reported the band to another site) | CY1: 3 Number of Red Knots (at this location) | CZ1: 3 Band/Flag Codes for Red Knots (for each individual list: band/flag code, orientation, color, and positions - upper left, lower left, upper right, lower right, and if you reported the band to another site) | DA1: 3 Number of Snowy Plovers (at this location) | DB1: 3 Band/Flag Codes for Snowy Plover (for each individual list: band/flag code, orientation, color, and positions - upper left, lower left, upper right, lower right, and if you reported the band to another site) | DC1: 3 Number of Wilson's Plovers (at this location) | DD1: 3 Band/Flag Codes for Wilson's Plover (for each individual list: band/flag code, orientation, color, and positions - upper left, lower left, upper right, lower right, and if you reported the band to another site) | DE1: 3 Any other non-focal species you want to include and information about bands | DF1: Do you have more group or focal points to enter? | DG1: Point 4 Latitude (in decimal degrees), for example, the latitude for Tallahassee would be: 30.43812. You can use Google Map to get this. Right click on location, and choose "what's here". | DH1: Point 4 Longitude (in decimal degrees), for example, the latitude for Tallahassee would be: -84.28158. It is negative because it is 84W. | DI1: 4 Number of American Oystercatchers (at this location) | DJ1: 4 Band/Flag Codes for American Oystercatchers (for each individual list: band/flag code, orientation, color, and positions - upper left, lower left, upper right, lower right, and if you reported the band to another site) | DK1: 4 Number of Black Skimmers (at this location) | DL1: 4 Band/Flag Codes for Black Skimmers (for each individual list: band code and color and if you reported the band to another site) | DM1: 4 Number of Piping Plovers (at this location) | DN1: 4 Band/Flag Codes for Piping Plovers (for each individual list: band/flag code, orientation, color, and positions - upper left, lower left, upper right, lower right, and if you reported the band to another site) | DO1: 4 Number of Red Knots (at this location) | DP1: 4 Band/Flag Codes for Red Knots (for each individual list: band/flag code, orientation, color, and positions - upper left, lower left, upper right, lower right, and if you reported the band to another site) | DQ1: 4 Number of Snowy Plovers (at this location) | DR1: 4 Band/Flag Codes for Snowy Plover (for each individual list: band/flag code, orientation, color, and positions - upper left, lower left, upper right, lower right, and if you reported the band to another site) | DS1: 4 Number of Wilson's Plovers (at this location) | DT1: 4 Band/Flag Codes for Wilson's Plover (for each individual list: band/flag code, orientation, color, and positions - upper left, lower left, upper right, lower right, and if you reported the band to another site) | DU1: 4 Any other non-focal species you want to include and information about bands | DV1: Do you have more group or focal points to enter? | DW1: Point 5 Latitude (in decimal degrees), for example, the latitude for Tallahassee would be: 30.43812. You can use Google Map to get this. Right click on location, and choose "what's here". | DX1: Point 5 Longitude (in decimal degrees), for example, the latitude for Tallahassee would be: -84.28158. It is negative because it is 84W. | DY1: 5 Number of American Oystercatchers (at this location) | DZ1: 5 Band/Flag Codes for American Oystercatchers (for each individual list: band/flag code, orientation, color, and positions - upper left, lower left, upper right, lower right, and if you reported the band to another site) | EA1: 5 Number of Black Skimmers (at this location) | EB1: 5 Band/Flag Codes for Black Skimmers (for each individual list: band code and color and if you reported the band to another site) | EC1: 5 Number of Piping Plovers (at this location) | ED1: 5 Band/Flag Codes for Piping Plovers (for each individual list: band/flag code, orientation, color, and positions - upper left, lower left, upper right, lower right, and if you reported the band to another site) | EE1: 5 Number of Red Knots (at this location) | EF1: 5 Number of Snowy Plovers (at this location) | EG1: 5 Band/Flag Codes for Red Knots (for each individual list: band/flag code, orientation, color, and positions - upper left, lower left, upper right, lower right, and if you reported the band to another site) | EH1: 5 Band/Flag Codes for Snowy Plover (for each individual list: band/flag code, orientation, color, and positions - upper left, lower left, upper right, lower right, and if you reported the band to another site) | EI1: 5 Band/Flag Codes for Wilson's Plover (for each individual list: band/flag code, orientation, color, and positions - upper left, lower left, upper right, lower right, and if you reported the band to another site) | EJ1: 5 Number of Wilson's Plovers (at this location) | EK1: Any other non-focal species you want to include and information about bands | EL1: Do you have more group or focal points to enter? | EM1: Point 6 Latitude (in decimal degrees), for example, the latitude for Tallahassee would be: 30.43812. You can use Google Map to get this. Right click on location, and choose "what's here". | EN1: Point 6 Longitude (in decimal degrees), for example, the latitude for Tallahassee would be: -84.28158. It is negative because it is 84W. | EO1: 6 Number of American Oystercatchers (at this location) | EP1: 6 Band/Flag Codes for American Oystercatchers (for each individual list: band/flag code, orientation, color, and positions - upper left, lower left, upper right, lower right, and if you reported the band to another site) | EQ1: 6 Number of Black Skimmers (at this location) | ER1: 6 Band/Flag Codes for Black Skimmers (for each individual list: band code and color and if you reported the band to another site) | ES1: 6 Number of Piping Plovers (at this location) | ET1: 6 Band/Flag Codes for Piping Plovers (for each individual list: band/flag code, orientation, color, and positions - upper left, lower left, upper right, lower right, and if you reported the band to another site) | EU1: 6 Number of Red Knots (at this location) | EV1: 6 Band/Flag Codes for Red Knots (for each individual list: band/flag code, orientation, color, and positions - upper left, lower left, upper right, lower right, and if you reported the band to another site) | EW1: 6 Number of Snowy Plovers (at this location) | EX1: 6 Band/Flag Codes for Snowy Plover (for each individual list: band/flag code, orientation, color, and positions - upper left, lower left, upper right, lower right, and if you reported the band to another site) | EY1: 6 Number of Wilson's Plovers (at this location) | EZ1: 6 Band/Flag Codes for Wilson's Plover (for each individual list: band/flag code, orientation, color, and positions - upper left, lower left, upper right, lower right, and if you reported the band to another site) | FA1: 6 Any other non-focal species you want to include and information about bands | FB1: Do you have more group or focal points to enter? | FC1: Point 7 Latitude (in decimal degrees), for example, the latitude for Tallahassee would be: 30.43812. You can use Google Map to get this. Right click on location, and choose "what's here". | FD1: Point 7 Longitude (in decimal degrees), for example, the latitude for Tallahassee would be: -84.28158. It is negative because it is 84W. | FE1: 7 Number of American Oystercatchers (at this location) | FF1: 7 Band/Flag Codes for American Oystercatchers (for each individual list: band/flag code, orientation, color, and positions - upper left, lower left, upper right, lower right, and if you reported the band to another site) | FG1: 7 Number of Black Skimmers (at this location) | FH1: 7 Band/Flag Codes for Black Skimmers (for each individual list: band code and color and if you reported the band to another site) | FI1: 7 Number of Piping Plovers (at this location) | FJ1: 7 Band/Flag Codes for Piping Plovers (for each individual list: band/flag code, orientation, color, and positions - upper left, lower left, upper right, lower right, and if you reported the band to another site) | FK1: 8 Number of Red Knots (at this location) | FL1: 7 Band/Flag Codes for Red Knots (for each individual list: band/flag code, orientation, color, and positions - upper left, lower left, upper right, lower right, and if you reported the band to another site) | FM1: 7 Number of Snowy Plovers (at this location) | FN1: 7 Band/Flag Codes for Snowy Plover (for each individual list: band/flag code, orientation, color, and positions - upper left, lower left, upper right, lower right, and if you reported the band to another site) | FO1: 7 Number of Wilson's Plovers (at this location) | FP1: 7 Band/Flag Codes for Wilson's Plover (for each individual list: band/flag code, orientation, color, and positions - upper left, lower left, upper right, lower right, and if you reported the band to another site) | FQ1: 7 Any other non-focal species you want to include and information about bands | FR1: Do you have more group or focal points to enter? | FS1: Point 8 Latitude (in decimal degrees), for example, the latitude for Tallahassee would be: 30.43812. You can use Google Map to get this. Right click on location, and choose "what's here". | FT1: Point 8 Longitude (in decimal degrees), for example, the latitude for Tallahassee would be: -84.28158. It is negative because it is 84W. | FU1: 8 Number of American Oystercatchers (at this location) | FV1: 8 Band/Flag Codes for American Oystercatchers (for each individual list: band/flag code, orientation, color, and positions - upper left, lower left, upper right, lower right, and if you reported the band to another site) | FW1: 8 Number of Black Skimmers (at this location) | FX1: 8 Band/Flag Codes for Black Skimmers (for each individual list: band code and color and if you reported the band to another site) | FY1: 8 Number of Piping Plovers (at this location) | FZ1: 8 Band/Flag Codes for Piping Plovers (for each individual list: band/flag code, orientation, color, and positions - upper left, lower left, upper right, lower right, and if you reported the band to another site) | GA1: 8 Number of Red Knots (at this location) | GB1: 8 Band/Flag Codes for Red Knots (for each individual list: band/flag code, orientation, color, and positions - upper left, lower left, upper right, lower right, and if you reported the band to another site) | GC1: 8 Number of Snowy Plovers (at this location) | GD1: 8 Band/Flag Codes for Snowy Plover (for each individual list: band/flag code, orientation, color, and positions - upper left, lower left, upper right, lower right, and if you reported the band to another site) | GE1: 8 Number of Wilson's Plovers (at this location) | GF1: 8 Band/Flag Codes for Wilson's Plover (for each individual list: band/flag code, orientation, color, and positions - upper left, lower left, upper right, lower right, and if you reported the band to another site) | GG1: 8 Any other non-focal species you want to include and information about bands | GH1: Do you have more group or focal points to enter? | GI1: Point 9 Latitude (in decimal degrees), for example, the latitude for Tallahassee would be: 30.43812. You can use Google Map to get this. Right click on location, and choose "what's here". | GJ1: Point 9 Longitude (in decimal degrees), for example, the latitude for Tallahassee would be: -84.28158. It is negative because it is 84W. | GK1: 9 Number of American Oystercatchers (at this location) | GL1: 9 Band/Flag Codes for American Oystercatchers (for each individual list: band/flag code, orientation, color, and positions - upper left, lower left, upper right, lower right, and if you reported the band to another site) | GM1: 9 Number of Black Skimmers (at this location) | GN1: 9 Band/Flag Codes for Black Skimmers (for each individual list: band code and color and if you reported the band to another site) | GO1: 9 Number of Piping Plovers (at this location) | GP1: 9 Band/Flag Codes for Piping Plovers (for each individual list: band/flag code, orientation, color, and positions - upper left, lower left, upper right, lower right, and if you reported the band to another site) | GQ1: 9 Number of Red Knots (at this location) | GR1: 9 Band/Flag Codes for Red Knots (for each individual list: band/flag code, orientation, color, and positions - upper left, lower left, upper right, lower right, and if you reported the band to another site) | GS1: 9 Number of Snowy Plovers (at this location) | GT1: 9 Band/Flag Codes for Snowy Plover (for each individual list: band/flag code, orientation, color, and positions - upper left, lower left, upper right, lower right, and if you reported the band to another site) | GU1: 9 Number of Wilson's Plovers (at this location) | GV1: 9 Band/Flag Codes for Wilson's Plover (for each individual list: band/flag code, orientation, color, and positions - upper left, lower left, upper right, lower right, and if you reported the band to another site) | GW1: 9 Any other non-focal species you want to include and information about bands | GX1: Do you have more group or focal points to enter? | GY1: Point 10 Latitude (in decimal degrees), for example, the latitude for Tallahassee would be: 30.43812. You can use Google Map to get this. Right click on location, and choose "what's here". | GZ1: Point 10 Longitude (in decimal degrees), for example, the latitude for Tallahassee would be: -84.28158. It is negative because it is 84W. | HA1: 10 Number of American Oystercatchers (at this location) | HB1: 10 Band/Flag Codes for American Oystercatchers (for each individual list: band/flag code, orientation, color, and positions - upper left, lower left, upper right, lower right, and if you reported the band to another site) | HC1: 10 Number of Black Skimmers (at this location) | HD1: 10 Band/Flag Codes for Black Skimmers (for each individual list: band code and color and if you reported the band to another site) | HE1: 10 Number of Piping Plovers (at this location) | HF1: 10 Band/Flag Codes for Piping Plovers (for each individual list: band/flag code, orientation, color, and positions - upper left, lower left, upper right, lower right, and if you reported the band to another site) | HG1: 10 Number of Red Knots (at this location) | HH1: 10 Band/Flag Codes for Red Knots (for each individual list: band/flag code, orientation, color, and positions - upper left, lower left, upper right, lower right, and if you reported the band to another site) | HI1: 10 Number of Snowy Plovers (at this location) | HJ1: 10 Band/Flag Codes for Snowy Plover (for each individual list: band/flag code, orientation, color, and positions - upper left, lower left, upper right, lower right, and if you reported the band to another site) | HK1: 10 Number of Wilson's Plovers (at this location) | HL1: 10 Band/Flag Codes for Wilson's Plover (for each individual list: band/flag code, orientation, color, and positions - upper left, lower left, upper right, lower right, and if you reported the band to another site) | HM1: 10 Any other non-focal species you want to include and information about bands | HN1: Do you have more group or focal points to enter? | HO1: Point 11 Latitude (in decimal degrees), for example, the latitude for Tallahassee would be: 30.43812. You can use Google Map to get this. Right click on location, and choose "what's here". | HP1: Point 11 Longitude (in decimal degrees), for example, the latitude for Tallahassee would be: -84.28158. It is negative because it is 84W. | HQ1: 11 Number of American Oystercatchers (at this location) | HR1: 11 Band/Flag Codes for American Oystercatchers (for each individual list: band/flag code, orientation, color, and positions - upper left, lower left, upper right, lower right, and if you reported the band to another site) | HS1: 11 Number of Black Skimmers (at this location) | HT1: 11 Band/Flag Codes for Black Skimmers (for each individual list: band code and color and if you reported the band to another site) | HU1: 11 Number of Piping Plovers (at this location) | HV1: 11 Band/Flag Codes for Piping Plovers (for each individual list: band/flag code, orientation, color, and positions - upper left, lower left, upper right, lower right, and if you reported the band to another site) | HW1: 11 Number of Red Knots (at this location) | HX1: 11 Band/Flag Codes for Red Knots (for each individual list: band/flag code, orientation, color, and positions - upper left, lower left, upper right, lower right, and if you reported the band to another site) | HY1: 11 Number of Snowy Plovers (at this location) | HZ1: 11 Band/Flag Codes for Snowy Plover (for each individual list: band/flag code, orientation, color, and positions - upper left, lower left, upper right, lower right, and if you reported the band to another site) | IA1: 11 Number of Wilson's Plovers (at this location) | IB1: 11 Band/Flag Codes for Wilson's Plover (for each individual list: band/flag code, orientation, color, and positions - upper left, lower left, upper right, lower right, and if you reported the band to another site) | IC1: 11 Any other non-focal species you want to include and information about bands | ID1: Do you have more group or focal points to enter? | IE1: Point 12 Latitude (in decimal degrees), for example, the latitude for Tallahassee would be: 30.43812. You can use Google Map to get this. Right click on location, and choose "what's here". | IF1: Point 12 Longitude (in decimal degrees), for example, the latitude for Tallahassee would be: -84.28158. It is negative because it is 84W. | IG1: 12 Number of American Oystercatchers (at this location) | IH1: 12 Band/Flag Codes for American Oystercatchers (for each individual list: band/flag code, orientation, color, and positions - upper left, lower left, upper right, lower right, and if you reported the band to another site) | II1: 12 Number of Black Skimmers (at this location) | IJ1: 12 Band/Flag Codes for Black Skimmers (for each individual list: band code and color and if you reported the band to another site) | IK1: 12 Number of Piping Plovers (at this location) | IL1: 12 Band/Flag Codes for Piping Plovers (for each individual list: band/flag code, orientation, color, and positions - upper left, lower left, upper right, lower right, and if you reported the band to another site) | IM1: 12 Number of Red Knots (at this location) | IN1: 12 Band/Flag Codes for Red Knots (for each individual list: band/flag code, orientation, color, and positions - upper left, lower left, upper right, lower right, and if you reported the band to another site) | IO1: 12 Number of Snowy Plovers (at this location) | IP1: 12 Band/Flag Codes for Snowy Plover (for each individual list: band/flag code, orientation, color, and positions - upper left, lower left, upper right, lower right, and if you reported the band to another site) | IQ1: 12 Number of Wilson's Plovers (at this location) | IR1: 12 Band/Flag Codes for Wilson's Plover (for each individual list: band/flag code, orientation, color, and positions - upper left, lower left, upper right, lower right, and if you reported the band to another site) | IS1: 12 Any other non-focal species you want to include and information about bands | IT1: Do you have more group or focal points to enter? | IU1: Point 13 Latitude (in decimal degrees), for example, the latitude for Tallahassee would be: 30.43812. You can use Google Map to get this. Right click on location, and choose "what's here". | IV1: Point 13 Longitude (in decimal degrees), for example, the latitude for Tallahassee would be: -84.28158. It is negative because it is 84W. | IW1: 13 Number of American Oystercatchers (at this location) | IX1: 13 Band/Flag Codes for American Oystercatchers (for each individual list: band/flag code, orientation, color, and positions - upper left, lower left, upper right, lower right, and if you reported the band to another site) | IY1: 13 Number of Black Skimmers (at this location) | IZ1: 13 Band/Flag Codes for Black Skimmers (for each individual list: band code and color and if you reported the band to another site) | JA1: 13 Number of Piping Plovers (at this location) | JB1: 13 Band/Flag Codes for Piping Plovers (for each individual list: band/flag code, orientation, color, and positions - upper left, lower left, upper right, lower right, and if you reported the band to another site) | JC1: 13 Number of Red Knots (at this location) | JD1: 13 Band/Flag Codes for Red Knots (for each individual list: band/flag code, orientation, color, and positions - upper left, lower left, upper right, lower right, and if you reported the band to another site) | JE1: 13 Number of Snowy Plovers (at this location) | JF1: 13 Band/Flag Codes for Snowy Plover (for each individual list: band/flag code, orientation, color, and positions - upper left, lower left, upper right, lower right, and if you reported the band to another site) | JG1: 13 Number of Wilson's Plovers (at this location) | JH1: 13 Band/Flag Codes for Wilson's Plover (for each individual list: band/flag code, orientation, color, and positions - upper left, lower left, upper right, lower right, and if you reported the band to another site) | JI1: 13 Any other non-focal species you want to include and information about bands | JJ1: Do you have more group or focal points to enter? | JK1: Point 14 Latitude (in decimal degrees), for example, the latitude for Tallahassee would be: 30.43812. You can use Google Map to get this. Right click on location, and choose "what's here". | JL1: Point 14 Longitude (in decimal degrees), for example, the latitude for Tallahassee would be: -84.28158. It is negative because it is 84W. | JM1: 14 Number of American Oystercatchers (at this location) | JN1: 14 Band/Flag Codes for American Oystercatchers (for each individual list: band/flag code, orientation, color, and positions - upper left, lower left, upper right, lower right, and if you reported the band to another site) | JO1: 14 Number of Black Skimmers (at this location) | JP1: 14 Band/Flag Codes for Black Skimmers (for each individual list: band code and color and if you reported the band to another site) | JQ1: 14 Number of Piping Plovers (at this location) | JR1: 14 Band/Flag Codes for Piping Plovers (for each individual list: band/flag code, orientation, color, and positions - upper left, lower left, upper right, lower right, and if you reported the band to another site) | JS1: 14 Number of Red Knots (at this location) | JT1: 14 Band/Flag Codes for Red Knots (for each individual list: band/flag code, orientation, color, and positions - upper left, lower left, upper right, lower right, and if you reported the band to another site) | JU1: 14 Number of Snowy Plovers (at this location) | JV1: 14 Number of Wilson's Plovers (at this location) | JW1: 14 Band/Flag Codes for Snowy Plover (for each individual list: band/flag code, orientation, color, and positions - upper left, lower left, upper right, lower right, and if you reported the band to another site) | JX1: 14 Band/Flag Codes for Wilson's Plover (for each individual list: band/flag code, orientation, color, and positions - upper left, lower left, upper right, lower right, and if you reported the band to another site) | JY1: 14 Any other non-focal species you want to include and information about bands | JZ1: Do you have more group or focal points to enter? | KA1: Point 15 Latitude (in decimal degrees), for example, the latitude for Tallahassee would be: 30.43812. You can use Google Map to get this. Right click on location, and choose "what's here". | KB1: Point 15 Longitude (in decimal degrees), for example, the latitude for Tallahassee would be: -84.28158. It is negative because it is 84W. | KC1: 15 Number of American Oystercatchers (at this location) | KD1: 15 Band/Flag Codes for American Oystercatchers (for each individual list: band/flag code, orientation, color, and positions - upper left, lower left, upper right, lower right, and if you reported the band to another site) | KE1: 15 Number of Black Skimmers (at this location) | KF1: 15 Band/Flag Codes for Black Skimmers (for each individual list: band code and color and if you reported the band to another site) | KG1: 15 Number of Piping Plovers (at this location) | KH1: 15 Band/Flag Codes for Piping Plovers (for each individual list: band/flag code, orientation, color, and positions - upper left, lower left, upper right, lower right, and if you reported the band to another site) | KI1: 15 Number of Red Knots (at this location) | KJ1: 15 Band/Flag Codes for Red Knots (for each individual list: band/flag code, orientation, color, and positions - upper left, lower left, upper right, lower right, and if you reported the band to another site) | KK1: 15 Number of Snowy Plovers (at this location) | KL1: 15 Band/Flag Codes for Snowy Plover (for each individual list: band/flag code, orientation, color, and positions - upper left, lower left, upper right, lower right, and if you reported the band to another site) | KM1: 15 Number of Wilson's Plovers (at this location) | KN1: 15 Band/Flag Codes for Wilson's Plover (for each individual list: band/flag code, orientation, color, and positions - upper left, lower left, upper right, lower right, and if you reported the band to another site) | KO1: 15 Any other non-focal species you want to include and information about bands | KP1: Do you have more group or focal points to enter? | KQ1: Point 16 Latitude (in decimal degrees), for example, the latitude for Tallahassee would be: 30.43812. You can use Google Map to get this. Right click on location, and choose "what's here". | KR1: Point 16 Longitude (in decimal degrees), for example, the latitude for Tallahassee would be: -84.28158. It is negative because it is 84W. | KS1: 16 Number of American Oystercatchers (at this location) | KT1: 16 Band/Flag Codes for American Oystercatchers (for each individual list: band/flag code, orientation, color, and positions - upper left, lower left, upper right, lower right, and if you reported the band to another site) | KU1: 16 Number of Black Skimmers (at this location) | KV1: 16 Band/Flag Codes for Black Skimmers (for each individual list: band code and color and if you reported the band to another site) | KW1: 16 Number of Piping Plovers (at this location) | KX1: 16 Band/Flag Codes for Piping Plovers (for each individual list: band/flag code, orientation, color, and positions - upper left, lower left, upper right, lower right, and if you reported the band to another site) | KY1: 16 Number of Red Knots (at this location) | KZ1: 16 Band/Flag Codes for Red Knots (for each individual list: band/flag code, orientation, color, and positions - upper left, lower left, upper right, lower right, and if you reported the band to another site) | LA1: 16 Number of Snowy Plovers (at this location) | LB1: 16 Band/Flag Codes for Snowy Plover (for each individual list: band/flag code, orientation, color, and positions - upper left, lower left, upper right, lower right, and if you reported the band to another site) | LC1: 16 Band/Flag Codes for Wilson's Plover (for each individual list: band/flag code, orientation, color, and positions - upper left, lower left, upper right, lower right, and if you reported the band to another site) | LD1: 16 Number of Wilson's Plovers (at this location) | LE1: Any other non-focal species you want to include and information about bands | LF1: Do you have more group or focal points to enter? | LG1: Point 17 Latitude (in decimal degrees), for example, the latitude for Tallahassee would be: 30.43812. You can use Google Map to get this. Right click on location, and choose "what's here". | LH1: Point 17 Longitude (in decimal degrees), for example, the latitude for Tallahassee would be: -84.28158. It is negative because it is 84W. | LI1: 17 Number of American Oystercatchers (at this location) | LJ1: 17 Band/Flag Codes for American Oystercatchers (for each individual list: band/flag code, orientation, color, and positions - upper left, lower left, upper right, lower right, and if you reported the band to another site) | LK1: 17 Number of Black Skimmers (at this location) | LL1: 17 Band/Flag Codes for Black Skimmers (for each individual list: band code and color and if you reported the band to another site) | LM1: 17 Number of Piping Plovers (at this location) | LN1: 17 Band/Flag Codes for Piping Plovers (for each individual list: band/flag code, orientation, color, and positions - upper left, lower left, upper right, lower right, and if you reported the band to another site) | LO1: 17 Number of Red Knots (at this location) | LP1: 17 Band/Flag Codes for Red Knots (for each individual list: band/flag code, orientation, color, and positions - upper left, lower left, upper right, lower right, and if you reported the band to another site) | LQ1: 17 Number of Snowy Plovers (at this location) | LR1: 17 Band/Flag Codes for Snowy Plover (for each individual list: band/flag code, orientation, color, and positions - upper left, lower left, upper right, lower right, and if you reported the band to another site) | LS1: 17 Number of Wilson's Plovers (at this location) | LT1: 17 Band/Flag Codes for Wilson's Plover (for each individual list: band/flag code, orientation, color, and positions - upper left, lower left, upper right, lower right, and if you reported the band to another site) | LU1: 17 Any other non-focal species you want to include and information about bands | LV1: Do you have more group or focal points to enter? | LW1: Point 18 Latitude (in decimal degrees), for example, the latitude for Tallahassee would be: 30.43812. You can use Google Map to get this. Right click on location, and choose "what's here". | LX1: Point 18 Longitude (in decimal degrees), for example, the latitude for Tallahassee would be: -84.28158. It is negative because it is 84W. | LY1: 18 Number of American Oystercatchers (at this location) | LZ1: 18 Band/Flag Codes for American Oystercatchers (for each individual list: band/flag code, orientation, color, and positions - upper left, lower left, upper right, lower right, and if you reported the band to another site) | MA1: 18 Number of Black Skimmers (at this location) | MB1: 18 Band/Flag Codes for Black Skimmers (for each individual list: band code and color and if you reported the band to another site) | MC1: 18 Number of Piping Plovers (at this location) | MD1: 18 Band/Flag Codes for Piping Plovers (for each individual list: band/flag code, orientation, color, and positions - upper left, lower left, upper right, lower right, and if you reported the band to another site) | ME1: 18 Number of Red Knots (at this location) | MF1: 18 Band/Flag Codes for Red Knots (for each individual list: band/flag code, orientation, color, and positions - upper left, lower left, upper right, lower right, and if you reported the band to another site) | MG1: 18 Number of Snowy Plovers (at this location) | MH1: 18 Band/Flag Codes for Snowy Plover (for each individual list: band/flag code, orientation, color, and positions - upper left, lower left, upper right, lower right, and if you reported the band to another site) | MI1: 18 Number of Wilson's Plovers (at this location) | MJ1: 18 Band/Flag Codes for Wilson's Plover (for each individual list: band/flag code, orientation, color, and positions - upper left, lower left, upper right, lower right, and if you reported the band to another site) | MK1: Any other non-focal species you want to include and information about bands | ML1: Do you have more group or focal points to enter? | MM1: Point 19 Latitude (in decimal degrees), for example, the latitude for Tallahassee would be: 30.43812. You can use Google Map to get this. Right click on location, and choose "what's here". | MN1: Point 19 Longitude (in decimal degrees), for example, the latitude for Tallahassee would be: -84.28158. It is negative because it is 84W. | MO1: 19 Number of American Oystercatchers (at this location) | MP1: 19 Band/Flag Codes for American Oystercatchers (for each individual list: band/flag code, orientation, color, and positions - upper left, lower left, upper right, lower right, and if you reported the band to another site) | MQ1: 19 Number of Black Skimmers (at this location) | MR1: 19 Band/Flag Codes for Black Skimmers (for each individual list: band code and color and if you reported the band to another site) | MS1: 19 Number of Piping Plovers (at this location) | MT1: 19 Band/Flag Codes for Piping Plovers (for each individual list: band/flag code, orientation, color, and positions - upper left, lower left, upper right, lower right, and if you reported the band to another site) | MU1: 19 Number of Red Knots (at this location) | MV1: 19 Band/Flag Codes for Red Knots (for each individual list: band/flag code, orientation, color, and positions - upper left, lower left, upper right, lower right, and if you reported the band to another site) | MW1: 19 Number of Snowy Plovers (at this location) | MX1: 19 Band/Flag Codes for Snowy Plover (for each individual list: band/flag code, orientation, color, and positions - upper left, lower left, upper right, lower right, and if you reported the band to another site) | MY1: 19 Number of Wilson's Plovers (at this location) | MZ1: 19 Band/Flag Codes for Wilson's Plover (for each individual list: band/flag code, orientation, color, and positions - upper left, lower left, upper right, lower right, and if you reported the band to another site) | NA1: 19 Any other non-focal species you want to include and information about bands | NB1: If you have more focal points to enter, just put them in the box below and hit enter when you are ready to submit.
Y2: =SUM(Y4:Y278) -> 1297 | Z2: =SUM(Z4:Z278) -> 4170 | AA2: =SUM(AA4:AA278) -> 444
Y3: =COUNT(Y4:Y278) -> 12 | Z3: =COUNT(Z4:Z278) -> 32 | AA3: =COUNT(AA4:AA278) -> 4
A4: 43506.828 | B4: president@sevolusiaaudubon.org | C4: =O4 -> 27th Ave beachside New Smyrna Beach to NSB jetty at Ponce Inlet, Volusia County | D4: 43497 | E4: Don Picard, Richard Fasse | F4: 29.00969 | G4: -80.8779 | H4: 29.07278 | I4: -80.9125 | J4: 0.020833333 | K4: 60-70F | L4: Light Wind | M4: No Rain | N4: All birds (includes focal and banded) | O4: 27th Ave beachside New Smyrna Beach to NSB jetty at Ponce Inlet, Volusia County | P4: 0 | R4: 1 | AD4: 11 | AE4: 33 | AF4: 33 | AM4: 14 | AR4: 221 | AU4: 3 | AY4: 22 | BA4: 7 | BB4: 54 | BC4: 133 | BE4: 81 | BF4: 111 | BG4: 1 | BJ4: Yes | BK4: 29.044636 | BL4: -80.897745 | BM4: 0 | BN4: 0 | BO4: 221 | BP4: 0 | BQ4: 0 | BR4: 0 | BS4: 0 | BT4: 0 | BU4: 0 | BV4: 0 | BW4: 0 | BX4: 0 | BY4: 0 | BZ4: No, I didn't see any additional focal species
A5: 43500.788 | B5: donlocomm@aol.com | C5: 3-D, County=Hillsborough | D5: 43500 | E5: Lorraine Margeson Morgan Parks | J5: 0.30208333 | K5: 60-70F | L5: Calm | N5: All birds (includes focal and banded) | P5: 5 | AU5: 27 | AX5: 2 | BB5: 8 | BC5: 30 | BE5: 5 | BI5: 15 | BJ5: Yes | BK5: 27.822852 | BL5: -82.431822 | BM5: 3 | BZ5: Yes | CA5: 27.834068 | CB5: -82.440688 | CC5: 2 | CP5: No, I didn't see any more focal species
A6: 43513.906 | B6: bgarret@sfwmd.gov | C6: A1-FEB, County=Palm Beach | D6: 43497 | E6: Dan O'Malley, Brian Garrett, Doreen LePage | J6: 0.3125 | K6: 50-60F | L6: Light Wind | M6: No Rain | N6: All birds (includes focal and banded) | T6: 43 | U6: 38 | V6: 75 | W6: 12 | Y6: 200 | AP6: 12 | AV6: 128 | AX6: 350 | BI6: 525 | BJ6: No, I didn't see any focal species
A7: 43501.337 | B7: sam@ecological-associates.com | C7: ACNWR Golden Sands-Ambersands, County=Indian River | D7: 43500 | E7: Samantha Pessolano, Joseph Pessolano, Ryan Dulfer | J7: 0.375 | K7: 60-70F | L7: Light Wind | M7: No Rain | N7: All birds (includes focal and banded) | P7: 0 | AF7: 60 | AH7: 00 | AM7: 26 | BB7: 11 | BC7: 10 | BE7: 26 | BJ7: No, I didn't see any focal species
A8: 43508.331 | B8: sam@ecological-associates.com | C8: ACNWR Golden Sands-Ambersands, County=Indian River | D8: 43500 | E8: Samantha Pessolano, Joseph Pessolano, Ryan Dulfer | J8: 0.375 | K8: 60-70F | L8: Light Wind | M8: No Rain | N8: All birds (includes focal and banded) | AF8: 60 | AM8: 26 | BB8: 11 | BC8: 10 | BE8: 26 | BJ8: No, I didn't see any focal species
A9: 43523.402 | B9: pmaleko@ufl.edu | C9: Alligator Harbor North, County=Franklin | D9: 43502 | E9: Phillip Maleko | J9: 0.39375 | K9: 60-70F | L9: Calm | M9: No Rain | N9: All birds (includes focal and banded) | P9: 0 | S9: 10 | AE9: 1 | AG9: 31 | AS9: 7 | AY9: 2 | BF9: 3 | BJ9: No, I didn't see any focal species
A10: 43503.64 | B10: southmoonunder@mchsi.com | C10: =O10 -> Alligator Point - Mud Cove (route listed but no lat./long. in spreadsheet) | D10: 43502 | E10: John Murphy | F10: 29.89807 | G10: -84.34664 | H10: 29.89503 | I10: -84.36929 | J10: 0.3125 | K10: 50-60F | L10: Light Wind | M10: No Rain | N10: All birds (includes focal and banded) | O10: Alligator Point - Mud Cove (route listed but no lat./long. in spreadsheet) | P10: 1 | R10: 2 | AF10: 8 | AM10: 9 | AS10: 2 | AU10: 36 | AV10: 4 | AX10: 45 | AY10: 40 | BB10: 2 | BE10: 44 | BF10: 25 | BJ10: Yes | BK10: 29.89776 | BL10: -84.34716 | BM10: 1 | BN10: n/a | BO10: 0 | BQ10: 0 | BS10: 0 | BU10: 0 | BW10: 0 | BZ10: No, I didn't see any additional focal species
A11: 43503.301 | B11: marvin.friel@myfwc.com | C11: Alligator Point, County=Franklin | D11: 43502 | E11: Marvin Friel, Molly Tuma, Philip Makela | J11: 0.53472222 | K11: 70-80F | L11: Calm | M11: No Rain | N11: All birds (includes focal and banded) | P11: 7 | R11: 45 | S11: 2 | T11: 6 | AB11: 19 | AD11: 20 | AE11: 15 | AF11: 230 | AG11: 1 | AI11: 7 | AM11: 189 | AR11: 82 | AU11: 3 | AV11: 11 | AX11: 2 | AY11: 37 | BB11: 3 | BE11: 126 | BJ11: Yes | BK11: 29.90843 | BL11: -84.43123 | BM11: 2 | BN11: unbanded | BZ11: Yes | CA11: 29.914 | CB11: -84.4412 | CK11: 2 | CL11: S//W:BK female & X:X male | CO11: RUTU 3 | CP11: Yes | CQ11: 29.91501 | CR11: -84.44186 | DA11: 5 | DB11: BG:S(K/W)// female; b//K:b//K male; X:X female but missing lower right foot, (stump but walks and runs without much limp); X:X female, X:X male | DF11: Yes | DG11: 29.91864 | DH11: -84.44122 | DI11: 5 | DJ11: all unbanded, 4 paired up and one single individual | DK11: 82 | DL11: none | DM11: 0 | DO11: 20 | DP11: none | DU11: SAND 140, FOTE 37, WILL 180, BBPL 35, RBGU 110, HERG 3, CATE 7, BRPE 3, DUNL 2, RUTU 4, GRYE 6 | DV11: No, I didn't see any more focal species
A12: 43524.443 | B12: allison.conboy@FloridaDEP.gov | C12: Amelia Island State Park, County=Nassau | D12: 43497 | E12: Allison Conboy | F12: 30.52201 | G12: -81.44476 | H12: 30.53021 | I12: -81.43694 | J12: 0.34513889 | K12: 50-60F | L12: Medium Wind | M12: Light Rain | N12: All birds (includes focal and banded) | O12: cloudy, cool, 55 degrees with intermittent light rain. Ongoing beach renourishment project along Atlantic shoreline included presence of dredging equipment and heavy equipment operators. Large numbers of shorebirds camped out behind sand berm adjacent to outflow pipe sheltering from north wind. | P12: 0 | S12: 2 | AC12: 14 | AE12: 8 | AF12: 61 | AG12: 771 | AM12: 17 | AN12: 17 | AR12: 74 | AS12: 19 | AU12: 8 | AY12: 50 | BA12: 1 | BB12: 95 | BC12: 111 | BE12: 16 | BF12: 14 | BJ12: Yes | BK12: 30.51493 | BL12: -81.43837 | BM12: 0 | BN12: na | BO12: 74 | BP12: no bands visible | BQ12: 0 | BR12: na | BS12: 0 | BT12: na | BU12: 0 | BV12: na | BW12: 0 | BX12: na | BY12: Large mixed roosting flock of gulls, terns, pelican and skimmers at southern point. no bands visible | BZ12: Yes | CA12: 30.5173 | CB12: -81.43525 | CC12: 0 | CD12: na | CE12: 0 | CF12: na | CG12: 11 | CH12: 1. Wf[MA];_:m,_. 2. Of,bR(fade):x,G. 3. Gf[76E],_xO,_. 4. x,B/R:_,bluedot | CI12: 0 | CJ12: na | CL12: 0 | CM12: 0 | CN12: na | CO12: Foraging along shoreline; hard to get clear readings on all bands. Blue dot is orange band with blue dot in center. | CP12: Yes | CQ12: 30.51788 | CR12: -81.43475 | CS12: 0 | CT12: na | CU12: 0 | CV12: na | CW12: 1 | CX12: not banded | CY12: 0 | CZ12: na | DA12: 0 | DB12: na | DC12: 17 | DD12: no bands visible | DE12: Large roosting mixed flock with 770 Semipalmated Plovers, 17 Wilson's Plovers, 1 Piping Plover, 35 Sanderling, 5 Ruddy Turnstones and 2 Dunlin. Roosting south and behind dredging sand berm pile to avoid north wind. No bands visible or readable. | DF12: Yes | DG12: 30.5183 | DH12: -81.4342 | DI12: 0 | DJ12: na | DK12: 0 | DL12: na | DM12: 2 | DN12: none banded | DO12: 0 | DP12: na | DQ12: 0 | DR12: na | DS12: 0 | DT12: na | DU12: 2 PIPL foraging along shoreline by dredge outflow. Not banded. | DV12: No, I didn't see any more focal species
A13: 43506.466 | B13: Janell.Brush@myfwc.com | C13: Amelia River ICW | D13: 43503 | E13: Pat Leary, Doris Leary | F13: 30.703184 | G13: -81.480606 | H13: 30.558113 | I13: -81.470645 | J13: 0.36805556 | K13: 50-60F | L13: Light Wind | M13: No Rain | N13: All birds (includes focal and banded) | O13: Route Name = Amelia River ICW. Encountered large flocks of mixed shorebird species (>2,500 total). Was not able to directly count these birds, mostly composed of BBPL, DUNL, WESA, SEPL, LESA, RUTU, SBDO instead entered min counts for these species. This way they show up in the list but counts for these species are not representative of the actual numbers of individuals observed along this route. | P13: 145 | R13: 100 | S13: 1000 | V13: 100 | Z13: 500 | AE13: 100 | AG13: 100 | AK13: 1000 | AM13: 88 | AR13: 1 | BJ13: Yes | BK13: 30.703184 | BL13: -81.480606 | BM13: 56 | BN13: 8 banded - submitted to AMOY WG | BO13: 1 | BZ13: Yes | CA13: 30.616075 | CB13: -81.489897 | CC13: 9 | CD13: 1 banded - submitted to AMOY WG | CP13: Yes | CQ13: 30.578738 | CR13: -81.460988 | CS13: 78 | CT13: 1 read and submitted to AMOY WG - more but concealed by dock edge | DF13: Yes | DG13: 30.558113 | DH13: -81.470645 | DI13: 2 | DJ13: 1 banded and submitted to AMOY WG | DV13: No, I didn't see any more focal species
A14: 43503.612 | B14: mypuffins@gmail.com | C14: Anastasia State Park Back Bay, County=St. Johns | D14: 43501 | E14: S. Killeen, J. DePue, D. Jones, J. Olbert | J14: 0.072916667 | K14: 70-80F | L14: Light Wind | M14: No Rain | N14: All birds (includes focal and banded) | R14: 3 | AE14: 2 | AF14: 7 | AG14: 55 | AU14: 2 | AX14: 5 | BC14: 3 | BE14: 3 | BF14: 6 | BJ14: No, I didn't see any focal species
A15: 43503.608 | B15: mypuffins@gmail.com | C15: Anastasia State Park Beach, County=St. Johns | D15: 43501 | E15: S. Killeen, J. DePue, D. Jones, J. Olbert | J15: 0.01875 | K15: 70-80F | L15: Light Wind | M15: No Rain | N15: All birds (includes focal and banded) | R15: 7 | S15: 86 | V15: 2 | AD15: 32 | AE15: 18 | AF15: 53 | AG15: 561 | AK15: 118 | AM15: 4 | AN15: 23 | AR15: 3 | AU15: 17 | AX15: 2 | AY15: 4 | BB15: 1 | BC15: 34 | BD15: 1 | BE15: 12 | BF15: 47 | BJ15: Yes | BK15: 29.86812 | BL15: -81.26827 | BO15: 3 | BP15: None banded | BY15: 2 BBPL, 11ROYT (1 banded USFWS Right leg; 1 banded USFWS left leg), 4 FOTE, 6 Sand, 2 RUTU, 1 WILL, 7 RBGU, 13 LAGU | BZ15: Yes | CA15: 29.87019 | CB15: -81.26926 | CM15: 9 | CN15: NO BANDS NOTED | CO15: 103 SEPL, 8 SAND, 6 DUNL, 2 RUTU, 3 WESA, 3 BBPL, 1 WILL | CP15: Yes | CQ15: 29.87888 | CR15: -81.27171 | CY15: 4 | CZ15: NO BANDS NOTED | DC15: 12 | DD15: NO BANDS NOTED birds were resting in the dunes | DE15: 393 SEPL, 79 DUNL, 27 SAND, 6 RUTU, 111 WESA, 2 LESA, 2 BBPL, 1 LBBG, 1 HERG, 2 WILL | DF15: Yes | DG15: 29.8952 | DH15: -81.2759 | DS15: 2 | DT15: NOT BANDED | DV15: Yes | DW15: 29.90197 | DX15: -81.27676 | EE15: 32 | EG15: NO BANDS NOTED | EL15: No, I didn't see any focal species
A16: 43503.636 | B16: mypuffins@gmail.com | C16: Anastasia State Park Beach, County=St. Johns | D16: 43501 | E16: S. Killeen, J. Depue, D. Jones, J. Olbert | J16: 0.01875 | K16: 70-80F | L16: Light Wind | M16: No Rain | N16: All birds (includes focal and banded) | O16: Porpoise Point | R16: 7 | S16: 86 | V16: 2 | AD16: 32 | AE16: 18 | AF16: 53 | AG16: 561 | AK16: 118 | AM16: 4 | AN16: 23 | AR16: 3 | AU16: 17 | AX16: 2 | AY16: 4 | BB16: 1 | BC16: 34 | BD16: 1 | BE16: 12 | BF16: 47 | BJ16: Yes | BK16: 29.86812 | BL16: -81.26827 | BO16: 3 | BP16: None banded | BY16: 2BBPL, 11 ROYT (1 banded USFWS right leg, 1 banded USFWS left leg), 4 FOTE, 6 SAND, 2 RUTU, 1 WILL, 7 RBGU, 13 LAGU | BZ16: Yes | CA16: 29.87119 | CB16: -81.26926 | CM16: 9 | CN16: NO BANDS NOTED | CO16: 103 SEOL, 8 SAND, 6 DUNL, 3 WESA, 3 BBPL, 1 WILL | CP16: Yes | CQ16: 29.87888 | CR16: -81.27171 | CY16: 4 | CZ16: NO BANDS NOTED | DC16: 12 | DD16: NO BANDS NOTED birds were resting in the dunes | DE16: 393 SEPL, 79 DUNL, 27 SAND, 6 RUTU, 111 WESA, 2 LESA, 2 BBPL, 1 LBBG, 1 HERG, 2 WILL | DF16: Yes | DG16: 29.8952 | DH16: -81.2759 | DS16: 2 | DT16: NOT BANDED | DV16: Yes | DW16: 29.90197 | DX16: -81.27676 | EE16: 32 | EG16: NO BANDS NOTED | EL16: No, I didn't see any focal species
A17: 43499.419 | B17: daniel.larremore@dep.state.fl.us | C17: Anclote Key North (Pasco), County=Pasco | D17: 43497 | E17: Dan Larremore, Colby Klein | J17: 0.42430556 | K17: 60-70F | L17: Light Wind | M17: No Rain | N17: All birds (includes focal and banded) | P17: 2 | R17: 24 | S17: 65 | AC17: 4 | AE17: 23 | AF17: 85 | AG17: 50 | AI17: 15 | AM17: 46 | AU17: 20 | AY17: 12 | BC17: 9 | BE17: 45 | BF17: 52 | BJ17: Yes | BK17: 28.213561 | BL17: -82.846671 | BM17: 0 | BO17: 0 | BQ17: 4 | BR17: no bands seen | BS17: 0 | BU17: 0 | BW17: 0 | BY17: greg7 reeg2 lbhe9, sppl20, pipl4, dunl25, bbpl2, will2, lesp1, | BZ17: Yes | CA17: 28.21565 | CB17: -82.847989 | CC17: 2 | CD17: no bands seen | CE17: 0 | CG17: 0 | CI17: 0 | CK17: 9 | CL17: Y.K-S.K, b.O-Y.Y, S.O-.O Band resights sent to RPruner | CM17: 0 | CO17: snpl9(3b) amoy2 royt40 brpe15, will12, dunl30 sand40, fote12 lagu9, rbgu20 | CP17: Yes | CQ17: 28.192427 | CR17: -82.85117 | CS17: 0 | CU17: 0 | CW17: 0 | CY17: 0 | DA17: 1 | DB17: no bands | DC17: 0 | DE17: sand25, SNPL1 | DF17: Yes | DG17: 28.173174 | DH17: -82.850075 | DI17: 0 | DK17: 0 | DM17: 0 | DO17: 0 | DQ17: 5 | DR17: no bands seen | DS17: 0 | DV17: No, I didn't see any more focal species
A18: 43501.361 | B18: daniel.larremore@dep.state.fl.us | C18: Anclote Key South (Pinellas), County=Pinellas | D18: 43497 | E18: Dave Perkey, Jeanne Trottier | J18: 0.38541667 | K18: 60-70F | L18: Light Wind | M18: No Rain | N18: All birds (includes focal and banded) | P18: 2 | R18: 9 | S18: 22 | AC18: 2 | AD18: 65 | AE18: 24 | AF18: 37 | AG18: 8 | AI18: 14 | AM18: 25 | AU18: 35 | AV18: 2 | AX18: 35 | AY18: 52 | BC18: 52 | BE18: 4 | BF18: 170 | BJ18: Yes | BK18: 28.15738 | BL18: -82.83688 | BM18: 0 | BO18: 0 | BQ18: 0 | BS18: 0 | BU18: 0 | BW18: 0 | BY18: ROYT 65, LAGU2, RBGU2, SAND1, RUTU1, WILL1, FOTE7 | BZ18: Yes | CA18: 28.15738 | CB18: -82.8378 | CC18: 0 | CE18: 0 | CG18: 2 | CH18: no bands seen | CI18: 11 | CJ18: no bands seen | CK18: 1 | CL18: no bands seen | CM18: 0 | CO18: SPPL1, RUTU2, SAND3 | CP18: Yes | CQ18: 28.15672 | CR18: -82.83841 | CS18: 2 | CT18: no bands seen | CU18: 0 | CW18: 0 | CY18: 17 | CZ18: no bands seen | DA18: 3 | DB18: no bands seen | DC18: 0 | DE18: ROYT30, WILL12, RBGU1, RUTU4, SAND14 SPPL2, DUNL19 | DF18: Yes | DG18: 28.15762 | DH18: -82.84158 | DI18: 0 | DK18: 0 | DM18: 0 | DO18: 26 | DP18: No bands seen | DQ18: 4 | DR18: no bands seen | DS18: 0 | DU18: WILL1, SAND11, DUNL3, | DV18: Yes | DW18: 28.125679 | DX18: -82.84238 | DY18: 0 | EA18: 0 | EC18: 0 | EE18: 10 | EF18: 0 | EG18: No bands seen | EJ18: 0 | EK18: WILL1, SAND11, BBPL4, SPPL5, RUTU2 | EL18: Yes | EM18: 28.15863 | EN18: -82.84465 | EO18: 0 | EQ18: 0 | ES18: 0 | EU18: 1 | EV18: No bands seen | EW18: 1 | EX18: No bands seen | EY18: 0 | FA18: SAND2, REEG1(white phase) | FB18: Yes | FC18: 28.16348 | FD18: -82.84736 | FE18: 0 | FG18: 0 | FI18: 0 | FK18: 0 | FM18: 1 | FN18: no bands seen | FO18: 0 | FR18: Yes | FS18: 28.16348 | FT18: -82.84902 | FU18: 0 | FW18: 0 | FY18: 0 | GA18: 0 | GC18: 4 | GD18: no bands seen | GE18: 0 | GH18: No, I didn't see any more focal species
A19: 43504.524 | B19: caity.reiland-smith@myfwc.com | C19: Apalachicola Breakwater, County=Franklin | D19: 43501 | E19: Caity Reiland-Smith, Ezra Thompson | J19: 0.48263889 | K19: 50-60F | L19: Calm | M19: No Rain | N19: All birds (includes focal and banded) | P19: 3 | BE19: 1 | BJ19: Yes | BK19: 29.7086 | BL19: -85.01141 | BM19: 3 | BN19: R//:R//S - Y53 - triangle | BO19: 0 | BP19: 0 | BQ19: 0 | BR19: 0 | BS19: 0 | BT19: 0 | BU19: 0 | BV19: 0 | BW19: 0 | BX19: 0 | BY19: 0 | BZ19: No, I didn't see any additional focal species
A20: 43503.626 | B20: clipps@audubon.org | C20: =O20 -> Apalachicola River Delta | D20: 43501 | E20: Chris Lipps | F20: 29.78405 | G20: -84.91085 | H20: 29.73406 | I20: -84.96765 | J20: 0.41805556 | K20: 60-70F | L20: Calm | M20: No Rain | N20: All birds (includes focal and banded) | O20: Apalachicola River Delta | P20: 2 | R20: 18 | S20: 50 | V20: 50 | W20: 4 | Z20: 1 | AS20: 8 | AU20: 4 | AV20: 3 | AY20: 28 | BE20: 18 | BF20: 00 | BJ20: Yes | BK20: 29.7581 | BL20: -84.9278 | BM20: 0 | BO20: 0 | BQ20: 0 | BS20: 0 | BU20: 0 | BW20: 0 | BY20: Rin-billed Gull:14, Forster's Tern:11, Dunlin:about 50, Least Sandpiper:about 50, Bonaparte's gull:2 | BZ20: Yes | CA20: 29.73853 | CB20: -84.9636 | CC20: 2 | CD20: 2 unbanded AMOY | CE20: 0 | CG20: 0 | CI20: 0 | CK20: 0 | CM20: 0 | CO20: Tricolored Heron:1 | CP20: No, I didn't see any more focal species
A21: 43510.493 | B21: kmartin@pbcgov.org | C21: Atlantic Dunes Park to Palm Beach (Monceau Court), County=Palm Beach | D21: 43500 | E21: TJ Steinhoff, Tori Hanley | J21: 0.42847222 | N21: All birds (includes focal and banded) | U21: 23 | AE21: 76 | AF21: 98 | AG21: 1 | AY21: 1 | BC21: 247 | BD21: 24 | BE21: 163 | BF21: 86 | BG21: 19 | BJ21: No, I didn't see any focal species
A22: 43502.377 | B22: Janice.Duquesnel@dep.state.fl.us | C22: Bahia Honda State Park, County=Monroe | D22: 43500 | E22: Janice Duquesnel | J22: 0.60625 | K22: 70-80F | L22: Calm | M22: No Rain | N22: All birds (includes focal and banded) | P22: 0 | AE22: 72 | AF22: 101 | AG22: 7 | AH22: 5 | AU22: 5 | BB22: 1 | BC22: 3 | BE22: 1 | BJ22: Yes | BK22: 24.6606 | BL22: -81.26795 | BM22: 0 | BN22: 0 | BO22: 0 | BP22: 0 | BQ22: 0 | BR22: 0 | BS22: 0 | BT22: 0 | BU22: 0 | BV22: 0 | BW22: 0 | BX22: 0 | BY22: sanderling, semipalmated sandpiper and ruddy turnstones | BZ22: No, I didn't see any focal species
A23: 43509.386 | B23: Janice.Duquesnel@dep.state.fl.us | C23: Bahia Honda State Park, County=Monroe | D23: 43500 | E23: Janice Duquesnel | J23: 0.60625 | K23: 70-80F | L23: Calm | M23: No Rain | N23: All birds (includes focal and banded) | P23: 0 | AE23: 72 | AF23: 101 | AG23: 7 | AH23: 5 | AU23: 5 | BB23: 1 | BC23: 3 | BE23: 1 | BJ23: Yes | BK23: 24.6606 | BL23: -81.26795 | BM23: 0 | BN23: 0 | BO23: 0 | BP23: 0 | BQ23: 0 | BR23: 0 | BS23: 0 | BT23: 0 | BU23: 0 | BV23: 0 | BW23: 0 | BX23: 0 | BY23: observed sanderlings, semipalmated sandpipers and ruddy turnstones at this coordinate - total of 152 birds at this site | BZ23: No, I didn't see any additional focal species
A24: 43503.649 | B24: clipps@audubon.org | C24: Bald Point South, County=Franklin | D24: 43502 | E24: Chris Lipps | J24: 0.49027778 | K24: 60-70F | L24: Calm | M24: No Rain | N24: All birds (includes focal and banded) | P24: 0 | R24: 1 | AM24: 3 | AY24: 50 | BE24: 20 | BJ24: Yes | BK24: 29.90498 | BL24: -84.34029 | BM24: 0 | BO24: 0 | BQ24: 0 | BS24: 0 | BU24: 0 | BW24: 0 | BY24: Forster's Tern:50, Ring-billed Gull:15 | BZ24: No, I didn't see any additional focal species
